Workbook
Name 乙: 計算用!$B$90
Name 冠帯: 計算用!$B$105
Name 逆行: 計算用!$AA$2:$AK$23
Name 建禄: 計算用!$B$106
Name 己: 計算用!$B$94
Name 庚: 計算用!$B$95
Name 甲: 計算用!$B$89
Name 死: 計算用!$B$110
Name 順行: 計算用!$O$2:$Z$23
Name 辛: 計算用!$B$96
Name 壬: 計算用!$B$97
Name 衰: 計算用!$B$108
Name 絶: 計算用!$B$100
Name 胎: 計算用!$B$101
Name 丁: 計算用!$B$92
Name 長生: 計算用!$B$103
Name 帝旺: 計算用!$B$107
Name 病: 計算用!$B$109
Name 丙: 計算用!$B$91
Name 墓: 計算用!$B$111
Name 戊: 計算用!$B$93
Name 養: 計算用!$B$102
Name 沐浴: 計算用!$B$104
Name 癸: 計算用!$B$98

Sheet 計算用
C1: 1 | D1: 2 | E1: 3 | F1: 4 | G1: 5 | H1: 6 | I1: 7 | J1: 8 | K1: 9 | L1: 10 | O1: 順行 | AA1: 逆行
B2: 0 | C2: ０~10 | D2: 11~20 | E2: 21~30 | F2: 31~40 | G2: 41~50 | H2: 51~60 | I2: 61~70 | J2: 71~80 | K2: 81~90 | L2: 91~100 | O2: 甲 | P2: 乙 | Q2: 丙 | R2: 丁 | S2: 戊 | T2: 己 | U2: 庚 | V2: 辛 | W2: 壬 | X2: 癸 | Y2: 甲 | Z2: 乙 | AA2: =INDIRECT(ADDRESS(ROW(),26-(COLUMN()-27))) -> 乙 | AB2: =INDIRECT(ADDRESS(ROW(),26-(COLUMN()-27))) -> 甲 | AC2: =INDIRECT(ADDRESS(ROW(),26-(COLUMN()-27))) -> 癸 | AD2: =INDIRECT(ADDRESS(ROW(),26-(COLUMN()-27))) -> 壬 | AE2: =INDIRECT(ADDRESS(ROW(),26-(COLUMN()-27))) -> 辛 | AF2: =INDIRECT(ADDRESS(ROW(),26-(COLUMN()-27))) -> 庚 | AG2: =INDIRECT(ADDRESS(ROW(),26-(COLUMN()-27))) -> 己 | AH2: =INDIRECT(ADDRESS(ROW(),26-(COLUMN()-27))) -> 戊 | ... AK2: =INDIRECT(ADDRESS(ROW(),26-(COLUMN()-27))) -> 乙 | AM2: 甲 | AN2: 寅
B3: 1 | C3: 0~1 | D3: 2~11 | E3: 12~21 | F3: 22~31 | G3: 32~41 | H3: 42~51 | I3: 52~61 | J3: 62~71 | K3: 72~81 | L3: 82~91 | O3: 乙 | P3: 丙 | Q3: 丁 | R3: 戊 | S3: 己 | T3: 庚 | U3: 辛 | V3: 壬 | W3: 癸 | X3: 甲 | Y3: 乙 | Z3: 丙 | AA3: =INDIRECT(ADDRESS(ROW(),26-(COLUMN()-27))) -> 丙 | AB3: =INDIRECT(ADDRESS(ROW(),26-(COLUMN()-27))) -> 乙 | AC3: =INDIRECT(ADDRESS(ROW(),26-(COLUMN()-27))) -> 甲 | AD3: =INDIRECT(ADDRESS(ROW(),26-(COLUMN()-27))) -> 癸 | AE3: =INDIRECT(ADDRESS(ROW(),26-(COLUMN()-27))) -> 壬 | AF3: =INDIRECT(ADDRESS(ROW(),26-(COLUMN()-27))) -> 辛 | AG3: =INDIRECT(ADDRESS(ROW(),26-(COLUMN()-27))) -> 庚 | AH3: =INDIRECT(ADDRESS(ROW(),26-(COLUMN()-27))) -> 己 | ... AK3: =INDIRECT(ADDRESS(ROW(),26-(COLUMN()-27))) -> 丙 | AM3: 甲 | AN3: 辰
B4: 2 | C4: 0~2 | D4: 3~12 | E4: 13~22 | F4: 23~32 | G4: 33~42 | H4: 43~52 | I4: 53~62 | J4: 63~72 | K4: 73~82 | L4: 83~92 | O4: 丙 | P4: 丁 | Q4: 戊 | R4: 己 | S4: 庚 | T4: 辛 | U4: 壬 | V4: 癸 | W4: 甲 | X4: 乙 | Y4: 丙 | Z4: 丁 | AA4: =INDIRECT(ADDRESS(ROW(),26-(COLUMN()-27))) -> 丁 | AB4: =INDIRECT(ADDRESS(ROW(),26-(COLUMN()-27))) -> 丙 | AC4: =INDIRECT(ADDRESS(ROW(),26-(COLUMN()-27))) -> 乙 | AD4: =INDIRECT(ADDRESS(ROW(),26-(COLUMN()-27))) -> 甲 | AE4: =INDIRECT(ADDRESS(ROW(),26-(COLUMN()-27))) -> 癸 | AF4: =INDIRECT(ADDRESS(ROW(),26-(COLUMN()-27))) -> 壬 | AG4: =INDIRECT(ADDRESS(ROW(),26-(COLUMN()-27))) -> 辛 | AH4: =INDIRECT(ADDRESS(ROW(),26-(COLUMN()-27))) -> 庚 | ... AK4: =INDIRECT(ADDRESS(ROW(),26-(COLUMN()-27))) -> 丁 | AM4: 甲 | AN4: 午
B5: 3 | C5: 0~3 | D5: 4~13 | E5: 14~23 | F5: 24~33 | G5: 34~43 | H5: 44~53 | I5: 54~63 | J5: 64~73 | K5: 74~83 | L5: 84~93 | O5: 丁 | P5: 戊 | Q5: 己 | R5: 庚 | S5: 辛 | T5: 壬 | U5: 癸 | V5: 甲 | W5: 乙 | X5: 丙 | Y5: 丁 | Z5: 戊 | AA5: =INDIRECT(ADDRESS(ROW(),26-(COLUMN()-27))) -> 戊 | AB5: =INDIRECT(ADDRESS(ROW(),26-(COLUMN()-27))) -> 丁 | AC5: =INDIRECT(ADDRESS(ROW(),26-(COLUMN()-27))) -> 丙 | AD5: =INDIRECT(ADDRESS(ROW(),26-(COLUMN()-27))) -> 乙 | AE5: =INDIRECT(ADDRESS(ROW(),26-(COLUMN()-27))) -> 甲 | AF5: =INDIRECT(ADDRESS(ROW(),26-(COLUMN()-27))) -> 癸 | AG5: =INDIRECT(ADDRESS(ROW(),26-(COLUMN()-27))) -> 壬 | AH5: =INDIRECT(ADDRESS(ROW(),26-(COLUMN()-27))) -> 辛 | ... AK5: =INDIRECT(ADDRESS(ROW(),26-(COLUMN()-27))) -> 戊 | AM5: 甲 | AN5: 申
B6: 4 | C6: 0~4 | D6: 5~14 | E6: 15~24 | F6: 25~34 | G6: 35~44 | H6: 45~54 | I6: 55~64 | J6: 65~74 | K6: 75~84 | L6: 85~94 | O6: 戊 | P6: 己 | Q6: 庚 | R6: 辛 | S6: 壬 | T6: 癸 | U6: 甲 | V6: 乙 | W6: 丙 | X6: 丁 | Y6: 戊 | Z6: 己 | AA6: =INDIRECT(ADDRESS(ROW(),26-(COLUMN()-27))) -> 己 | AB6: =INDIRECT(ADDRESS(ROW(),26-(COLUMN()-27))) -> 戊 | AC6: =INDIRECT(ADDRESS(ROW(),26-(COLUMN()-27))) -> 丁 | AD6: =INDIRECT(ADDRESS(ROW(),26-(COLUMN()-27))) -> 丙 | AE6: =INDIRECT(ADDRESS(ROW(),26-(COLUMN()-27))) -> 乙 | AF6: =INDIRECT(ADDRESS(ROW(),26-(COLUMN()-27))) -> 甲 | AG6: =INDIRECT(ADDRESS(ROW(),26-(COLUMN()-27))) -> 癸 | AH6: =INDIRECT(ADDRESS(ROW(),26-(COLUMN()-27))) -> 壬 | ... AK6: =INDIRECT(ADDRESS(ROW(),26-(COLUMN()-27))) -> 己 | AM6: 甲 | AN6: 戌
B7: 5 | C7: 0~5 | D7: 6~15 | E7: 16~25 | F7: 26~35 | G7: 36~45 | H7: 46~55 | I7: 56~65 | J7: 66~75 | K7: 76~85 | L7: 86~95 | O7: 己 | P7: 庚 | Q7: 辛 | R7: 壬 | S7: 癸 | T7: 甲 | U7: 乙 | V7: 丙 | W7: 丁 | X7: 戊 | Y7: 己 | Z7: 庚 | AA7: =INDIRECT(ADDRESS(ROW(),26-(COLUMN()-27))) -> 庚 | AB7: =INDIRECT(ADDRESS(ROW(),26-(COLUMN()-27))) -> 己 | AC7: =INDIRECT(ADDRESS(ROW(),26-(COLUMN()-27))) -> 戊 | AD7: =INDIRECT(ADDRESS(ROW(),26-(COLUMN()-27))) -> 丁 | AE7: =INDIRECT(ADDRESS(ROW(),26-(COLUMN()-27))) -> 丙 | AF7: =INDIRECT(ADDRESS(ROW(),26-(COLUMN()-27))) -> 乙 | AG7: =INDIRECT(ADDRESS(ROW(),26-(COLUMN()-27))) -> 甲 | AH7: =INDIRECT(ADDRESS(ROW(),26-(COLUMN()-27))) -> 癸 | ... AK7: =INDIRECT(ADDRESS(ROW(),26-(COLUMN()-27))) -> 庚 | AM7: 甲 | AN7: 子
B8: 6 | C8: 0~6 | D8: 7~16 | E8: 17~26 | F8: 27~36 | G8: 37~46 | H8: 47~56 | I8: 57~66 | J8: 67~76 | K8: 77~86 | L8: 87~96 | O8: 庚 | P8: 辛 | Q8: 壬 | R8: 癸 | S8: 甲 | T8: 乙 | U8: 丙 | V8: 丁 | W8: 戊 | X8: 己 | Y8: 庚 | Z8: 辛 | AA8: =INDIRECT(ADDRESS(ROW(),26-(COLUMN()-27))) -> 辛 | AB8: =INDIRECT(ADDRESS(ROW(),26-(COLUMN()-27))) -> 庚 | AC8: =INDIRECT(ADDRESS(ROW(),26-(COLUMN()-27))) -> 己 | AD8: =INDIRECT(ADDRESS(ROW(),26-(COLUMN()-27))) -> 戊 | AE8: =INDIRECT(ADDRESS(ROW(),26-(COLUMN()-27))) -> 丁 | AF8: =INDIRECT(ADDRESS(ROW(),26-(COLUMN()-27))) -> 丙 | AG8: =INDIRECT(ADDRESS(ROW(),26-(COLUMN()-27))) -> 乙 | AH8: =INDIRECT(ADDRESS(ROW(),26-(COLUMN()-27))) -> 甲 | ... AK8: =INDIRECT(ADDRESS(ROW(),26-(COLUMN()-27))) -> 辛 | AM8: 乙 | AN8: 卯
B9: 7 | C9: 0~7 | D9: 8~17 | E9: 18~27 | F9: 28~37 | G9: 38~47 | H9: 48~57 | I9: 58~67 | J9: 68~77 | K9: 78~87 | L9: 88~97 | O9: 辛 | P9: 壬 | Q9: 癸 | R9: 甲 | S9: 乙 | T9: 丙 | U9: 丁 | V9: 戊 | W9: 己 | X9: 庚 | Y9: 辛 | Z9: 壬 | AA9: =INDIRECT(ADDRESS(ROW(),26-(COLUMN()-27))) -> 壬 | AB9: =INDIRECT(ADDRESS(ROW(),26-(COLUMN()-27))) -> 辛 | AC9: =INDIRECT(ADDRESS(ROW(),26-(COLUMN()-27))) -> 庚 | AD9: =INDIRECT(ADDRESS(ROW(),26-(COLUMN()-27))) -> 己 | AE9: =INDIRECT(ADDRESS(ROW(),26-(COLUMN()-27))) -> 戊 | AF9: =INDIRECT(ADDRESS(ROW(),26-(COLUMN()-27))) -> 丁 | AG9: =INDIRECT(ADDRESS(ROW(),26-(COLUMN()-27))) -> 丙 | AH9: =INDIRECT(ADDRESS(ROW(),26-(COLUMN()-27))) -> 乙 | ... AK9: =INDIRECT(ADDRESS(ROW(),26-(COLUMN()-27))) -> 壬 | AM9: 乙 | AN9: 巳
B10: 8 | C10: 0~8 | D10: 9~18 | E10: 19~28 | F10: 29~38 | G10: 39~48 | H10: 49~58 | I10: 59~68 | J10: 69~78 | K10: 79~88 | L10: 89~98 | O10: 壬 | P10: 癸 | Q10: 甲 | R10: 乙 | S10: 丙 | T10: 丁 | U10: 戊 | V10: 己 | W10: 庚 | X10: 辛 | Y10: 壬 | Z10: 癸 | AA10: =INDIRECT(ADDRESS(ROW(),26-(COLUMN()-27))) -> 癸 | AB10: =INDIRECT(ADDRESS(ROW(),26-(COLUMN()-27))) -> 壬 | AC10: =INDIRECT(ADDRESS(ROW(),26-(COLUMN()-27))) -> 辛 | AD10: =INDIRECT(ADDRESS(ROW(),26-(COLUMN()-27))) -> 庚 | AE10: =INDIRECT(ADDRESS(ROW(),26-(COLUMN()-27))) -> 己 | AF10: =INDIRECT(ADDRESS(ROW(),26-(COLUMN()-27))) -> 戊 | AG10: =INDIRECT(ADDRESS(ROW(),26-(COLUMN()-27))) -> 丁 | AH10: =INDIRECT(ADDRESS(ROW(),26-(COLUMN()-27))) -> 丙 | ... AK10: =INDIRECT(ADDRESS(ROW(),26-(COLUMN()-27))) -> 癸 | AM10: 乙 | AN10: 未
B11: 9 | C11: 0~9 | D11: 10~19 | E11: 20~29 | F11: 30~39 | G11: 40~49 | H11: 50~59 | I11: 60~69 | J11: 70~79 | K11: 80~89 | L11: 90~99 | O11: 癸 | P11: 甲 | Q11: 乙 | R11: 丙 | S11: 丁 | T11: 戊 | U11: 己 | V11: 庚 | W11: 辛 | X11: 壬 | Y11: 癸 | Z11: 甲 | AA11: =INDIRECT(ADDRESS(ROW(),26-(COLUMN()-27))) -> 甲 | AB11: =INDIRECT(ADDRESS(ROW(),26-(COLUMN()-27))) -> 癸 | AC11: =INDIRECT(ADDRESS(ROW(),26-(COLUMN()-27))) -> 壬 | AD11: =INDIRECT(ADDRESS(ROW(),26-(COLUMN()-27))) -> 辛 | AE11: =INDIRECT(ADDRESS(ROW(),26-(COLUMN()-27))) -> 庚 | AF11: =INDIRECT(ADDRESS(ROW(),26-(COLUMN()-27))) -> 己 | AG11: =INDIRECT(ADDRESS(ROW(),26-(COLUMN()-27))) -> 戊 | AH11: =INDIRECT(ADDRESS(ROW(),26-(COLUMN()-27))) -> 丁 | ... AK11: =INDIRECT(ADDRESS(ROW(),26-(COLUMN()-27))) -> 甲 | AM11: 乙 | AN11: 酉
B12: 10 | C12: 0 | D12: 1~10 | E12: 11~20 | F12: 21~30 | G12: 31~40 | H12: 41~50 | I12: 51~60 | J12: 61~70 | K12: 71~80 | L12: 81~90 | O12: 子 | P12: 丑 | Q12: 寅 | R12: 卯 | S12: 辰 | T12: 巳 | U12: 午 | V12: 未 | W12: 申 | X12: 酉 | Y12: 戌 | Z12: 亥 | AA12: =INDIRECT(ADDRESS(ROW(),26-(COLUMN()-27))) -> 亥 | AB12: =INDIRECT(ADDRESS(ROW(),26-(COLUMN()-27))) -> 戌 | AC12: =INDIRECT(ADDRESS(ROW(),26-(COLUMN()-27))) -> 酉 | AD12: =INDIRECT(ADDRESS(ROW(),26-(COLUMN()-27))) -> 申 | AE12: =INDIRECT(ADDRESS(ROW(),26-(COLUMN()-27))) -> 未 | AF12: =INDIRECT(ADDRESS(ROW(),26-(COLUMN()-27))) -> 午 | AG12: =INDIRECT(ADDRESS(ROW(),26-(COLUMN()-27))) -> 巳 | AH12: =INDIRECT(ADDRESS(ROW(),26-(COLUMN()-27))) -> 辰 | ... AK12: =INDIRECT(ADDRESS(ROW(),26-(COLUMN()-27))) -> 丑 | AM12: 乙 | AN12: 亥
C13: 比肩 | D13: 劫財 | E13: 食神 | F13: 傷官 | G13: 偏財 | H13: 正財 | I13: 偏官 | J13: 正官 | K13: 偏印 | L13: 印綬 | O13: 丑 | P13: 寅 | Q13: 卯 | R13: 辰 | S13: 巳 | T13: 午 | U13: 未 | V13: 申 | W13: 酉 | X13: 戌 | Y13: 亥 | Z13: 子 | AA13: =INDIRECT(ADDRESS(ROW(),26-(COLUMN()-27))) -> 子 | AB13: =INDIRECT(ADDRESS(ROW(),26-(COLUMN()-27))) -> 亥 | AC13: =INDIRECT(ADDRESS(ROW(),26-(COLUMN()-27))) -> 戌 | AD13: =INDIRECT(ADDRESS(ROW(),26-(COLUMN()-27))) -> 酉 | AE13: =INDIRECT(ADDRESS(ROW(),26-(COLUMN()-27))) -> 申 | AF13: =INDIRECT(ADDRESS(ROW(),26-(COLUMN()-27))) -> 未 | AG13: =INDIRECT(ADDRESS(ROW(),26-(COLUMN()-27))) -> 午 | AH13: =INDIRECT(ADDRESS(ROW(),26-(COLUMN()-27))) -> 巳 | ... AK13: =INDIRECT(ADDRESS(ROW(),26-(COLUMN()-27))) -> 寅 | AM13: 乙 | AN13: 丑
C14: 活動 | D14: 浪費 | E14: 調整 | F14: 焦燥 | G14: 投資 | H14: 成果 | I14: 転換 | J14: 完結 | K14: 整理 | L14: 学習 | O14: 寅 | P14: 卯 | Q14: 辰 | R14: 巳 | S14: 午 | T14: 未 | U14: 申 | V14: 酉 | W14: 戌 | X14: 亥 | Y14: 子 | Z14: 丑 | AA14: =INDIRECT(ADDRESS(ROW(),26-(COLUMN()-27))) -> 丑 | AB14: =INDIRECT(ADDRESS(ROW(),26-(COLUMN()-27))) -> 子 | AC14: =INDIRECT(ADDRESS(ROW(),26-(COLUMN()-27))) -> 亥 | AD14: =INDIRECT(ADDRESS(ROW(),26-(COLUMN()-27))) -> 戌 | AE14: =INDIRECT(ADDRESS(ROW(),26-(COLUMN()-27))) -> 酉 | AF14: =INDIRECT(ADDRESS(ROW(),26-(COLUMN()-27))) -> 申 | AG14: =INDIRECT(ADDRESS(ROW(),26-(COLUMN()-27))) -> 未 | AH14: =INDIRECT(ADDRESS(ROW(),26-(COLUMN()-27))) -> 午 | ... AK14: =INDIRECT(ADDRESS(ROW(),26-(COLUMN()-27))) -> 卯 | AM14: 丙 | AN14: 辰
B15: 日干 | C15: 甲 | D15: 乙 | E15: 丙 | F15: 丁 | G15: 戊 | H15: 己 | I15: 庚 | J15: 辛 | K15: 壬 | L15: 癸 | O15: 卯 | P15: 辰 | Q15: 巳 | R15: 午 | S15: 未 | T15: 申 | U15: 酉 | V15: 戌 | W15: 亥 | X15: 子 | Y15: 丑 | Z15: 寅 | AA15: =INDIRECT(ADDRESS(ROW(),26-(COLUMN()-27))) -> 寅 | AB15: =INDIRECT(ADDRESS(ROW(),26-(COLUMN()-27))) -> 丑 | AC15: =INDIRECT(ADDRESS(ROW(),26-(COLUMN()-27))) -> 子 | AD15: =INDIRECT(ADDRESS(ROW(),26-(COLUMN()-27))) -> 亥 | AE15: =INDIRECT(ADDRESS(ROW(),26-(COLUMN()-27))) -> 戌 | AF15: =INDIRECT(ADDRESS(ROW(),26-(COLUMN()-27))) -> 酉 | AG15: =INDIRECT(ADDRESS(ROW(),26-(COLUMN()-27))) -> 申 | AH15: =INDIRECT(ADDRESS(ROW(),26-(COLUMN()-27))) -> 未 | ... AK15: =INDIRECT(ADDRESS(ROW(),26-(COLUMN()-27))) -> 辰 | AM15: 丙 | AN15: 午
B16: 甲 | C16: 比肩 | D16: 劫財 | E16: 食神 | F16: 傷官 | G16: 偏財 | H16: 正財 | I16: 偏官 | J16: 正官 | K16: 偏印 | L16: 印綬 | O16: 辰 | P16: 巳 | Q16: 午 | R16: 未 | S16: 申 | T16: 酉 | U16: 戌 | V16: 亥 | W16: 子 | X16: 丑 | Y16: 寅 | Z16: 卯 | AA16: =INDIRECT(ADDRESS(ROW(),26-(COLUMN()-27))) -> 卯 | AB16: =INDIRECT(ADDRESS(ROW(),26-(COLUMN()-27))) -> 寅 | AC16: =INDIRECT(ADDRESS(ROW(),26-(COLUMN()-27))) -> 丑 | AD16: =INDIRECT(ADDRESS(ROW(),26-(COLUMN()-27))) -> 子 | AE16: =INDIRECT(ADDRESS(ROW(),26-(COLUMN()-27))) -> 亥 | AF16: =INDIRECT(ADDRESS(ROW(),26-(COLUMN()-27))) -> 戌 | AG16: =INDIRECT(ADDRESS(ROW(),26-(COLUMN()-27))) -> 酉 | AH16: =INDIRECT(ADDRESS(ROW(),26-(COLUMN()-27))) -> 申 | ... AK16: =INDIRECT(ADDRESS(ROW(),26-(COLUMN()-27))) -> 巳 | AM16: 丙 | AN16: 申
B17: 乙 | C17: 劫財 | D17: 比肩 | E17: 傷官 | F17: 食神 | G17: 正財 | H17: 偏財 | I17: 正官 | J17: 偏官 | K17: 印綬 | L17: 偏印 | O17: 巳 | P17: 午 | Q17: 未 | R17: 申 | S17: 酉 | T17: 戌 | U17: 亥 | V17: 子 | W17: 丑 | X17: 寅 | Y17: 卯 | Z17: 辰 | AA17: =INDIRECT(ADDRESS(ROW(),26-(COLUMN()-27))) -> 辰 | AB17: =INDIRECT(ADDRESS(ROW(),26-(COLUMN()-27))) -> 卯 | AC17: =INDIRECT(ADDRESS(ROW(),26-(COLUMN()-27))) -> 寅 | AD17: =INDIRECT(ADDRESS(ROW(),26-(COLUMN()-27))) -> 丑 | AE17: =INDIRECT(ADDRESS(ROW(),26-(COLUMN()-27))) -> 子 | AF17: =INDIRECT(ADDRESS(ROW(),26-(COLUMN()-27))) -> 亥 | AG17: =INDIRECT(ADDRESS(ROW(),26-(COLUMN()-27))) -> 戌 | AH17: =INDIRECT(ADDRESS(ROW(),26-(COLUMN()-27))) -> 酉 | ... AK17: =INDIRECT(ADDRESS(ROW(),26-(COLUMN()-27))) -> 午 | AM17: 丙 | AN17: 戌
B18: 丙 | C18: 偏印 | D18: 印綬 | E18: 比肩 | F18: 劫財 | G18: 食神 | H18: 傷官 | I18: 偏財 | J18: 正財 | K18: 偏官 | L18: 正官 | O18: 午 | P18: 未 | Q18: 申 | R18: 酉 | S18: 戌 | T18: 亥 | U18: 子 | V18: 丑 | W18: 寅 | X18: 卯 | Y18: 辰 | Z18: 巳 | AA18: =INDIRECT(ADDRESS(ROW(),26-(COLUMN()-27))) -> 巳 | AB18: =INDIRECT(ADDRESS(ROW(),26-(COLUMN()-27))) -> 辰 | AC18: =INDIRECT(ADDRESS(ROW(),26-(COLUMN()-27))) -> 卯 | AD18: =INDIRECT(ADDRESS(ROW(),26-(COLUMN()-27))) -> 寅 | AE18: =INDIRECT(ADDRESS(ROW(),26-(COLUMN()-27))) -> 丑 | AF18: =INDIRECT(ADDRESS(ROW(),26-(COLUMN()-27))) -> 子 | AG18: =INDIRECT(ADDRESS(ROW(),26-(COLUMN()-27))) -> 亥 | AH18: =INDIRECT(ADDRESS(ROW(),26-(COLUMN()-27))) -> 戌 | ... AK18: =INDIRECT(ADDRESS(ROW(),26-(COLUMN()-27))) -> 未 | AM18: 丙 | AN18: 子
B19: 丁 | C19: 印綬 | D19: 偏印 | E19: 劫財 | F19: 比肩 | G19: 傷官 | H19: 食神 | I19: 正財 | J19: 偏財 | K19: 正官 | L19: 偏官 | O19: 未 | P19: 申 | Q19: 酉 | R19: 戌 | S19: 亥 | T19: 子 | U19: 丑 | V19: 寅 | W19: 卯 | X19: 辰 | Y19: 巳 | Z19: 午 | AA19: =INDIRECT(ADDRESS(ROW(),26-(COLUMN()-27))) -> 午 | AB19: =INDIRECT(ADDRESS(ROW(),26-(COLUMN()-27))) -> 巳 | AC19: =INDIRECT(ADDRESS(ROW(),26-(COLUMN()-27))) -> 辰 | AD19: =INDIRECT(ADDRESS(ROW(),26-(COLUMN()-27))) -> 卯 | AE19: =INDIRECT(ADDRESS(ROW(),26-(COLUMN()-27))) -> 寅 | AF19: =INDIRECT(ADDRESS(ROW(),26-(COLUMN()-27))) -> 丑 | AG19: =INDIRECT(ADDRESS(ROW(),26-(COLUMN()-27))) -> 子 | AH19: =INDIRECT(ADDRESS(ROW(),26-(COLUMN()-27))) -> 亥 | ... AK19: =INDIRECT(ADDRESS(ROW(),26-(COLUMN()-27))) -> 申 | AM19: 丙 | AN19: 寅
B20: 戊 | C20: 偏官 | D20: 正官 | E20: 偏印 | F20: 印綬 | G20: 比肩 | H20: 劫財 | I20: 食神 | J20: 傷官 | K20: 偏財 | L20: 正財 | O20: 申 | P20: 酉 | Q20: 戌 | R20: 亥 | S20: 子 | T20: 丑 | U20: 寅 | V20: 卯 | W20: 辰 | X20: 巳 | Y20: 午 | Z20: 未 | AA20: =INDIRECT(ADDRESS(ROW(),26-(COLUMN()-27))) -> 未 | AB20: =INDIRECT(ADDRESS(ROW(),26-(COLUMN()-27))) -> 午 | AC20: =INDIRECT(ADDRESS(ROW(),26-(COLUMN()-27))) -> 巳 | AD20: =INDIRECT(ADDRESS(ROW(),26-(COLUMN()-27))) -> 辰 | AE20: =INDIRECT(ADDRESS(ROW(),26-(COLUMN()-27))) -> 卯 | AF20: =INDIRECT(ADDRESS(ROW(),26-(COLUMN()-27))) -> 寅 | AG20: =INDIRECT(ADDRESS(ROW(),26-(COLUMN()-27))) -> 丑 | AH20: =INDIRECT(ADDRESS(ROW(),26-(COLUMN()-27))) -> 子 | ... AK20: =INDIRECT(ADDRESS(ROW(),26-(COLUMN()-27))) -> 酉 | AM20: 丁 | AN20: 巳
B21: 己 | C21: 正官 | D21: 偏官 | E21: 印綬 | F21: 偏印 | G21: 劫財 | H21: 比肩 | I21: 傷官 | J21: 食神 | K21: 正財 | L21: 偏財 | O21: 酉 | P21: 戌 | Q21: 亥 | R21: 子 | S21: 丑 | T21: 寅 | U21: 卯 | V21: 辰 | W21: 巳 | X21: 午 | Y21: 未 | Z21: 申 | AA21: =INDIRECT(ADDRESS(ROW(),26-(COLUMN()-27))) -> 申 | AB21: =INDIRECT(ADDRESS(ROW(),26-(COLUMN()-27))) -> 未 | AC21: =INDIRECT(ADDRESS(ROW(),26-(COLUMN()-27))) -> 午 | AD21: =INDIRECT(ADDRESS(ROW(),26-(COLUMN()-27))) -> 巳 | AE21: =INDIRECT(ADDRESS(ROW(),26-(COLUMN()-27))) -> 辰 | AF21: =INDIRECT(ADDRESS(ROW(),26-(COLUMN()-27))) -> 卯 | AG21: =INDIRECT(ADDRESS(ROW(),26-(COLUMN()-27))) -> 寅 | AH21: =INDIRECT(ADDRESS(ROW(),26-(COLUMN()-27))) -> 丑 | ... AK21: =INDIRECT(ADDRESS(ROW(),26-(COLUMN()-27))) -> 戌 | AM21: 丁 | AN21: 未
B22: 庚 | C22: 偏財 | D22: 正財 | E22: 偏官 | F22: 正官 | G22: 偏印 | H22: 印綬 | I22: 比肩 | J22: 劫財 | K22: 食神 | L22: 傷官 | O22: 戌 | P22: 亥 | Q22: 子 | R22: 丑 | S22: 寅 | T22: 卯 | U22: 辰 | V22: 巳 | W22: 午 | X22: 未 | Y22: 申 | Z22: 酉 | AA22: =INDIRECT(ADDRESS(ROW(),26-(COLUMN()-27))) -> 酉 | AB22: =INDIRECT(ADDRESS(ROW(),26-(COLUMN()-27))) -> 申 | AC22: =INDIRECT(ADDRESS(ROW(),26-(COLUMN()-27))) -> 未 | AD22: =INDIRECT(ADDRESS(ROW(),26-(COLUMN()-27))) -> 午 | AE22: =INDIRECT(ADDRESS(ROW(),26-(COLUMN()-27))) -> 巳 | AF22: =INDIRECT(ADDRESS(ROW(),26-(COLUMN()-27))) -> 辰 | AG22: =INDIRECT(ADDRESS(ROW(),26-(COLUMN()-27))) -> 卯 | AH22: =INDIRECT(ADDRESS(ROW(),26-(COLUMN()-27))) -> 寅 | ... AK22: =INDIRECT(ADDRESS(ROW(),26-(COLUMN()-27))) -> 亥 | AM22: 丁 | AN22: 酉
B23: 辛 | C23: 正財 | D23: 偏財 | E23: 正官 | F23: 偏官 | G23: 印綬 | H23: 偏印 | I23: 劫財 | J23: 比肩 | K23: 傷官 | L23: 食神 | O23: 亥 | P23: 子 | Q23: 丑 | R23: 寅 | S23: 卯 | T23: 辰 | U23: 巳 | V23: 午 | W23: 未 | X23: 申 | Y23: 酉 | Z23: 戌 | AA23: =INDIRECT(ADDRESS(ROW(),26-(COLUMN()-27))) -> 戌 | AB23: =INDIRECT(ADDRESS(ROW(),26-(COLUMN()-27))) -> 酉 | AC23: =INDIRECT(ADDRESS(ROW(),26-(COLUMN()-27))) -> 申 | AD23: =INDIRECT(ADDRESS(ROW(),26-(COLUMN()-27))) -> 未 | AE23: =INDIRECT(ADDRESS(ROW(),26-(COLUMN()-27))) -> 午 | AF23: =INDIRECT(ADDRESS(ROW(),26-(COLUMN()-27))) -> 巳 | AG23: =INDIRECT(ADDRESS(ROW(),26-(COLUMN()-27))) -> 辰 | AH23: =INDIRECT(ADDRESS(ROW(),26-(COLUMN()-27))) -> 卯 | ... AK23: =INDIRECT(ADDRESS(ROW(),26-(COLUMN()-27))) -> 子 | AM23: 丁 | AN23: 亥
B24: 壬 | C24: 食神 | D24: 傷官 | E24: 偏財 | F24: 正財 | G24: 偏官 | H24: 正官 | I24: 偏印 | J24: 印綬 | K24: 比肩 | L24: 劫財 | AM24: 丁 | AN24: 丑
B25: 癸 | C25: 傷官 | D25: 食神 | E25: 正財 | F25: 偏財 | G25: 正官 | H25: 偏官 | I25: 印綬 | J25: 偏印 | K25: 劫財 | L25: 比肩 | AM25: 丁 | AN25: 卯
AM26: 戊 | AN26: 午
C27: 子 | D27: 丑 | E27: 寅 | F27: 卯 | G27: 辰 | H27: 巳 | I27: 午 | J27: 未 | K27: 申 | L27: 酉 | M27: 戌 | N27: 亥 | AM27: 戊 | AN27: 申
B28: 甲 | C28: 沐浴 | D28: 冠帯 | E28: 建禄 | F28: 帝旺 | G28: 衰 | H28: 病 | I28: 死 | J28: 墓 | K28: 絶 | L28: 胎 | M28: 養 | N28: 長生 | P28: 甲 | Q28: 木 | S28: 木 | T28: 火 | U28: 土 | V28: 金 | W28: 水 | AM28: 戊 | AN28: 戌
B29: 乙 | C29: 病 | D29: 衰 | E29: 帝旺 | F29: 建禄 | G29: 冠帯 | H29: 沐浴 | I29: 長生 | J29: 養 | K29: 胎 | L29: 絶 | M29: 墓 | N29: 死 | P29: 乙 | Q29: 木 | S29: 火 | T29: 土 | U29: 金 | V29: 水 | W29: 木 | AM29: 戊 | AN29: 子
B30: 丙 | C30: 胎 | D30: 養 | E30: 長生 | F30: 沐浴 | G30: 冠帯 | H30: 建禄 | I30: 帝旺 | J30: 衰 | K30: 病 | L30: 死 | M30: 墓 | N30: 絶 | P30: 丙 | Q30: 火 | S30: 土 | T30: 金 | U30: 水 | V30: 木 | W30: 火 | AM30: 戊 | AN30: 寅
B31: 丁 | C31: 絶 | D31: 墓 | E31: 死 | F31: 病 | G31: 衰 | H31: 帝旺 | I31: 建禄 | J31: 冠帯 | K31: 沐浴 | L31: 長生 | M31: 養 | N31: 胎 | P31: 丁 | Q31: 火 | S31: 金 | T31: 水 | U31: 木 | V31: 火 | W31: 土 | AM31: 戊 | AN31: 辰
B32: 戊 | C32: 胎 | D32: 養 | E32: 長生 | F32: 沐浴 | G32: 冠帯 | H32: 建禄 | I32: 帝旺 | J32: 衰 | K32: 病 | L32: 死 | M32: 墓 | N32: 絶 | P32: 戊 | Q32: 土 | S32: 水 | T32: 木 | U32: 火 | V32: 土 | W32: 金 | AM32: 己 | AN32: 未
B33: 己 | C33: 絶 | D33: 墓 | E33: 死 | F33: 病 | G33: 衰 | H33: 帝旺 | I33: 建禄 | J33: 冠帯 | K33: 沐浴 | L33: 長生 | M33: 養 | N33: 胎 | P33: 己 | Q33: 土 | AM33: 己 | AN33: 酉
B34: 庚 | C34: 死 | D34: 墓 | E34: 絶 | F34: 胎 | G34: 養 | H34: 長生 | I34: 沐浴 | J34: 冠帯 | K34: 建禄 | L34: 帝旺 | M34: 衰 | N34: 病 | P34: 庚 | Q34: 金 | AM34: 己 | AN34: 亥
B35: 辛 | C35: 長生 | D35: 養 | E35: 胎 | F35: 絶 | G35: 墓 | H35: 死 | I35: 病 | J35: 衰 | K35: 帝旺 | L35: 建禄 | M35: 冠帯 | N35: 沐浴 | P35: 辛 | Q35: 金 | AM35: 己 | AN35: 丑
B36: 壬 | C36: 帝旺 | D36: 衰 | E36: 病 | F36: 死 | G36: 墓 | H36: 絶 | I36: 胎 | J36: 養 | K36: 長生 | L36: 沐浴 | M36: 冠帯 | N36: 建禄 | P36: 壬 | Q36: 水 | AM36: 己 | AN36: 卯
B37: 癸 | C37: 建禄 | D37: 冠帯 | E37: 沐浴 | F37: 長生 | G37: 養 | H37: 胎 | I37: 絶 | J37: 墓 | K37: 死 | L37: 病 | M37: 衰 | N37: 帝旺 | P37: 癸 | Q37: 水 | AM37: 己 | AN37: 巳
C38: 長生 | D38: 沐浴 | E38: 冠帯 | F38: 建禄 | G38: 帝旺 | H38: 衰 | I38: 病 | J38: 死 | K38: 墓 | L38: 絶 | M38: 胎 | N38: 養 | AM38: 庚 | AN38: 申
B39: 比肩 | C39: 活動 | D39: 亥 | E39: 戌 | F39: 酉 | G39: 申 | H39: 未 | I39: 午 | J39: 巳 | K39: 辰 | L39: 卯 | M39: 寅 | N39: 丑 | O39: 子 | P39: 比肩 | Q39: 自我の星 | R39: 守備本能 | S39: 社会や自分のルールを守って生きた方が才能が開花しやすい。 | T39: 【生一本なマイペース人間】【自分の意見を押し通しイエスと言わせたい】 | U39: 独立心旺盛で、自分の信じることを主張する。負けず嫌いなので、競争心や闘争心が強い。一歩一歩頑張る。自分で何かをしたい。これだと信じた道を貫いていく。早く自分のレールを見つける事が成功の秘訣。 | AM39: 庚 | AN39: 戌
B40: 劫財 | C40: 浪費 | D40: 癸 | E40: 壬 | F40: 辛 | G40: 庚 | H40: 己 | I40: 戊 | J40: 丁 | K40: 丙 | L40: 乙 | M40: 甲 | P40: 劫財 | Q40: 自我の星 | R40: 守備本能 | S40: 社会や自分のルールを守って生きた方が才能が開花しやすい。 | T40: 【社交的な頑張り屋】【人の意見を聞きながら自分の意見にイエスと言わせたい】 | U40: 表面は温和だが妥協はしない。負けず嫌い。人との駆け引きがうまい。人当たりがよく、外での評判はいいが、家族ではワンマンで口うるさくなりがち。外では頑張れる。組織をまとめるリーダータイプ。 | AM40: 庚 | AN40: 子
...

Sheet 原本
G2: 生年月日・生まれた時間 | L2: 出生地 | M2: 年齢 | N2: 性別
C3: 氏名 | D3: ［氏名］ | Q3: 五行判定
H4: A 元命式のみ | Q4: =IF($E$7="","",VLOOKUP(E7,計算用!$P$28:$Q$37,2,FALSE)) | R4: =IF($E$7="","",VLOOKUP($Q$4,計算用!$S$28:$W$32,2,FALSE)) | S4: =IF($E$7="","",VLOOKUP($Q$4,計算用!$S$28:$W$32,3,FALSE)) | T4: =IF($E$7="","",VLOOKUP($Q$4,計算用!$S$28:$W$32,4,FALSE)) | U4: =IF($E$7="","",VLOOKUP($Q$4,計算用!$S$28:$W$32,5,FALSE))
D6: 時柱 | E6: 日柱 | F6: 月柱 | G6: 年柱 | K6: ［点数］ | R6: 時柱 | S6: 日柱 | T6: 月柱 | U6: 年柱 | V6: 合計
C7: 干支 | Q7: 木 | V7: =SUM(R7:U7) -> 0
I8: ［点数］ | M8: ［点数］ | Q8: 火 | V8: =SUM(R8:U8) -> 0
C9: 蔵干 | Q9: 土 | V9: =SUM(R9:U9) -> 0
C10: 通変星 | Q10: 金 | V10: =SUM(R10:U10) -> 0
C11: 蔵干通変星 | Q11: 水 | V11: =SUM(R11:U11) -> 0
C12: 十二運星 | J12: ［点数］ | L12: ［点数］
C13: 空亡(天中殺)
N14: ※空亡：素直・反省・感謝を忘れずに。自我を無理に通すより流れに乗るとき。可能性を信じること。
C15: 今年の影響：木 8 → 9（+1）、水 8 → 12（+4）
C16: 大運の影響：木 9 → 8（-1）、火 4 → 6（+2）
C17: 差分・グラフの数値は配置確認用です。
B18: ●特殊な命式
C19: ［判定名］ | E19: ［正式な判定説明］ | Q19: ※傷官：細かいところに気が付く、プライドが高い、口の禍が起こりやすい。
C20: ［判定名］ | E20: ［正式な判定説明］
C21: ［判定名］ | E21: ［正式な判定説明］
C22: ［判定名］ | E22: ［正式な判定説明］
C23: ［判定名］ | E23: ［正式な判定説明］
C24: ［判定名］ | E24: ［正式な判定説明］
B25: ●干支から読み取れるもの
B29: ●通変星・蔵干通変星から読み取れるもの
C30: 幼年期 | I30: 青年期
C32: 成熟期 | I32: 老年期
Q33: 用神判定 | R33: =IF($E$7="","",VLOOKUP($E$7,計算用!$P$28:$Q$37,2,FALSE))
B34: ●本来の自分らしさ 現在段階：［人生段階］ ［通変星 × 蔵干通変星］
B36: ●十二運星から読み取れる性格
C37: 意思決定の時の自分（年柱） | I37: 初対面の人と会った時の自分（月柱）
C39: ［十二運星名］ キーワード：［正式キーワード］ | I39: ［十二運星名］ キーワード：［正式キーワード］
C40: 一人の時の自分（日柱） | I40: どんな老後を過ごしたいか（時柱）
C42: ［十二運星名］ キーワード：［正式キーワード］ | I42: ［十二運星名］ キーワード：［正式キーワード］
B43: ●考え方の傾向
C44: ＜右脳型・左脳型＞ | F44: ＜メリット・デメリット＞ | I44: ＜仕事4分類＞
C49: ＜目標への向かい方＞
B55: ●大運
C56: ［年齢帯］ | D56: ［年齢帯］ | E56: ［年齢帯］ | F56: ［年齢帯］ | G56: ［年齢帯］ | H56: ［年齢帯］ | I56: ［年齢帯］ | J56: ［年齢帯］ | K56: ［年齢帯］ | L56: ［年齢帯］
C57: ［通変星］ | D57: ［通変星］ | E57: ［通変星］ | F57: ［通変星］ | G57: ［通変星］ | H57: ［通変星］ | I57: ［通変星］ | J57: ［通変星］ | K57: ［通変星］ | L57: ［通変星］
C58: ［干］ | D58: ［干］ | E58: ［干］ | F58: ［干］ | G58: ［干］ | H58: ［干］ | I58: ［干］ | J58: ［干］ | K58: ［干］ | L58: ［干］
...
